<?xml version="1.0" ?>
<!-- =================================================================================== -->
<!-- |    This document was autogenerated by xacro from udacity_bot.xacro              | -->
<!-- |    EDITING THIS FILE BY HAND IS NOT RECOMMENDED                                 | -->
<!-- =================================================================================== -->
<robot name="udacity_bot" xmlns:xacro="http://www.ros.org/wiki/xacro">
  <!-- ################### XACRO Definitions ############################# -->
  <!-- ################### XACRO Definitions ############################# -->
  <!-- ################### XACRO Definitions ############################# -->
  <!-- ################### XACRO Definitions ############################# -->
  <!-- ################### XACRO Origins ############################# -->
  <!-- ################### XACRO Inertias ############################# -->
  <!-- ################### MACRO Generators ############################# -->
  <!-- ################### MACRO Generators ############################# -->
  <!-- ################### MACRO Generators ############################# -->
  <!-- ################### MACRO Generators ############################# -->
  <!-- ################### ROBOT Definitions ############################# -->
  <!-- ################### ROBOT Definitions ############################# -->
  <!-- ################### ROBOT Definitions ############################# -->
  <!-- ################### ROBOT Definitions ############################# -->
  <gazebo>
    <plugin filename="libgazebo_ros_diff_drive.so" name="differential_drive_controller">
      <robotNamespace>/udacity_bot</robotNamespace>
      <legacyMode>false</legacyMode>
      <alwaysOn>true</alwaysOn>
      <updateRate>10</updateRate>
      <leftJoint>left_wheel_hinge</leftJoint>
      <rightJoint>right_wheel_hinge</rightJoint>
      <wheelSeparation>0.4</wheelSeparation>
      <wheelDiameter>0.2</wheelDiameter>
      <torque>10</torque>
      <commandTopic>cmd_vel</commandTopic>
      <odometryTopic>odom</odometryTopic>
      <odometryFrame>odom</odometryFrame>
      <robotBaseFrame>robot_footprint</robotBaseFrame>
    </plugin>
  </gazebo>
  <gazebo reference="camera_link">
    <material>Gazebo/Green</material>
    <sensor name="camera1" type="camera">
      <update_rate>30.0</update_rate>
      <camera name="head">
        <horizontal_fov>1.3962634</horizontal_fov>
        <image>
          <width>800</width>
          <height>800</height>
          <format>R8G8B8</format>
        </image>
        <clip>
          <near>0.02</near>
          <far>300</far>
        </clip>
      </camera>
      <plugin filename="libgazebo_ros_camera.so" name="camera_controller">
        <robotNamespace>/udacity_bot</robotNamespace>
        <alwaysOn>true</alwaysOn>
        <updateRate>0.0</updateRate>
        <cameraName>udacity_bot/camera1</cameraName>
        <imageTopicName>image_raw</imageTopicName>
        <cameraInfoTopicName>camera_info</cameraInfoTopicName>
        <frameName>camera_link</frameName>
        <hackBaseline>0.07</hackBaseline>
        <distortionK1>0.0</distortionK1>
        <distortionK2>0.0</distortionK2>
        <distortionK3>0.0</distortionK3>
        <distortionT1>0.0</distortionT1>
        <distortionT2>0.0</distortionT2>
      </plugin>
    </sensor>
  </gazebo>
  <!-- hokuyo -->
  <gazebo reference="hokuyo_link">
    <sensor name="head_hokuyo_sensor" type="ray">
      <pose>0 0 0 0 0 0</pose>
      <visualize>false</visualize>
      <update_rate>40</update_rate>
      <ray>
        <scan>
          <horizontal>
            <samples>720</samples>
            <resolution>1</resolution>
            <min_angle>-1.570796</min_angle>
            <max_angle>1.570796</max_angle>
          </horizontal>
        </scan>
        <range>
          <min>0.10</min>
          <max>30.0</max>
          <resolution>0.01</resolution>
        </range>
        <noise>
          <type>gaussian</type>
          <!-- Noise parameters based on published spec for Hokuyo laser
               achieving "+-30mm" accuracy at range < 10m.  A mean of 0.0m and
               stddev of 0.01m will put 99.7% of samples within 0.03m of the true
               reading. -->
          <mean>0.0</mean>
          <stddev>0.01</stddev>
        </noise>
      </ray>
      <plugin filename="libgazebo_ros_laser.so" name="gazebo_ros_head_hokuyo_controller">
        <robotNamespace>/udacity_bot</robotNamespace>
        <topicName>/udacity_bot/laser/scan</topicName>
        <frameName>hokuyo_link</frameName>
      </plugin>
    </sensor>
  </gazebo>
  <link name="robot_footprint"/>
  <joint name="robot_footprint_joint" type="fixed">
    <origin rpy="0 0 0" xyz="0 0 0"/>
    <parent link="robot_footprint"/>
    <child link="chassis"/>
  </joint>
  <!-- BEGIN Chassis -->
  <link name="chassis">
    <pose>0 0 0.1 0 0 0</pose>
    <inertial>
      <mass value="15.0"/>
      <origin rpy=" 0 0 0" xyz="0.0 0 0"/>
      <inertia ixx="0.1" ixy="0" ixz="0" iyy="0.1" iyz="0" izz="0.1"/>
    </inertial>
    <collision name="collision">
      <origin rpy="0 0 0" xyz="0 0 0"/>
      <geometry>
        <box size=".4 .2 .1"/>
      </geometry>
    </collision>
    <visual name="chassis_visual">
      <origin rpy="0 0 0" xyz="0 0 0"/>
      <geometry>
        <box size=".4 .2 .1"/>
      </geometry>
    </visual>
    <collision name="back_caster_collision">
      <origin rpy=" 0 0 0" xyz="-0.15 0 -0.05"/>
      <geometry>
        <sphere radius="0.0499"/>
      </geometry>
    </collision>
    <visual name="back_caster_visual">
      <origin rpy=" 0 0 0" xyz="-0.15 0 -0.05"/>
      <geometry>
        <sphere radius="0.05"/>
      </geometry>
    </visual>
    <collision name="front_caster_collision">
      <origin rpy=" 0 0 0" xyz="0.15 0 -0.05"/>
      <geometry>
        <sphere radius="0.0499"/>
      </geometry>
    </collision>
    <visual name="front_caster_visual">
      <origin rpy=" 0 0 0" xyz="0.15 0 -0.05"/>
      <geometry>
        <sphere radius="0.05"/>
      </geometry>
    </visual>
  </link>
  <!-- END Chassis -->
  <!-- ################### LINK Definitions ############################# -->
  <!-- ################### LINK Definitions ############################# -->
  <!-- ################### LINK Definitions ############################# -->
  <!-- ################### LINK Definitions ############################# -->
  <link name="right_wheel">
    <inertial>
      <origin rpy="0 1.5707 1.5707" xyz="0 0 0"/>
      <mass value="5"/>
      <inertia ixx="0.1" ixy="0" ixz="0" iyy="0.1" iyz="0" izz="0.1"/>
    </inertial>
    <collision>
      <origin rpy="0 1.5707 1.5707" xyz="0 0 0"/>
      <!--UNITS IN METERS-->
      <!--<cylinder radius="" length=""/>-->
      <!--<box x="" y="" z="" />-->
      <!--<sphere radius=""/> -->
      <geometry>
        <cylinder length="0.05" radius="0.1"/>
      </geometry>
    </collision>
    <visual>
      <origin rpy="0 1.5707 1.5707" xyz="0 0 0"/>
      <!--UNITS IN METERS-->
      <!--<cylinder radius="" length=""/>-->
      <!--<box x="" y="" z="" />-->
      <!--<sphere radius=""/> -->
      <geometry>
        <cylinder length="0.05" radius="0.1"/>
      </geometry>
    </visual>
  </link>
  <gazebo reference="right_wheel">
    <!--<kp>1000.0</kp>-->
    <!--<kd>1000.0</kd>-->
    <!--<mu1>10.0</mu1>-->
    <!--<mu2>10.0</mu2>-->
    <material>Gazebo/Green</material>
  </gazebo>
  <link name="left_wheel">
    <inertial>
      <origin rpy="0 1.5707 1.5707" xyz="0 0 0"/>
      <mass value="5"/>
      <inertia ixx="0.1" ixy="0" ixz="0" iyy="0.1" iyz="0" izz="0.1"/>
    </inertial>
    <collision>
      <origin rpy="0 1.5707 1.5707" xyz="0 0 0"/>
      <!--UNITS IN METERS-->
      <!--<cylinder radius="" length=""/>-->
      <!--<box x="" y="" z="" />-->
      <!--<sphere radius=""/> -->
      <geometry>
        <cylinder length="0.05" radius="0.1"/>
      </geometry>
    </collision>
    <visual>
      <origin rpy="0 1.5707 1.5707" xyz="0 0 0"/>
      <!--UNITS IN METERS-->
      <!--<cylinder radius="" length=""/>-->
      <!--<box x="" y="" z="" />-->
      <!--<sphere radius=""/> -->
      <geometry>
        <cylinder length="0.05" radius="0.1"/>
      </geometry>
    </visual>
  </link>
  <gazebo reference="left_wheel">
    <!--<kp>1000.0</kp>-->
    <!--<kd>1000.0</kd>-->
    <!--<mu1>10.0</mu1>-->
    <!--<mu2>10.0</mu2>-->
    <material>Gazebo/Green</material>
  </gazebo>
  <!-- ################### JOINT Definitions ############################# -->
  <!-- ################### JOINT Definitions ############################# -->
  <!-- ################### JOINT Definitions ############################# -->
  <!-- ################### JOINT Definitions ############################# -->
  <joint name="right_wheel_hinge" type="continuous">
    <origin rpy="0 0 0" xyz="0 -0.15 0"/>
    <parent link="chassis"/>
    <child link="right_wheel"/>
    <axis rpy="0 0 0" xyz="0 1 0"/>
    <limit effort="10000" velocity="1000"/>
    <dynamics damping="1.0" friction="1.0"/>
  </joint>
  <joint name="left_wheel_hinge" type="continuous">
    <origin rpy="0 0 0" xyz="0 0.15 0"/>
    <parent link="chassis"/>
    <child link="left_wheel"/>
    <axis rpy="0 0 0" xyz="0 1 0"/>
    <limit effort="10000" velocity="1000"/>
    <dynamics damping="1.0" friction="1.0"/>
  </joint>
  <!--################### SENSOR Definitions ############################# -->
  <link name="camera_link">
    <inertial>
      <origin rpy="0 0 0" xyz="0 0 0"/>
      <!--<mass value="${min_mass}"/>-->
      <mass value="0.1"/>
      <inertia ixx="0.1" ixy="0" ixz="0" iyy="0.1" iyz="0" izz="0.1"/>
    </inertial>
    <collision>
      <origin rpy="0 0 0" xyz="0 0 0"/>
      <!--UNITS IN METERS-->
      <!--<cylinder radius="" length=""/>-->
      <!--<box x="" y="" z="" />-->
      <!--<sphere radius=""/> -->
      <geometry>
        <box size="0.05 0.05 0.05"/>
      </geometry>
    </collision>
    <visual>
      <origin rpy="0 0 0" xyz="0 0 0"/>
      <!--UNITS IN METERS-->
      <!--<cylinder radius="" length=""/>-->
      <!--<box x="" y="" z="" />-->
      <!--<sphere radius=""/> -->
      <geometry>
        <box size="0.05 0.05 0.05"/>
      </geometry>
    </visual>
  </link>
  <joint name="camera_joint" type="fixed">
    <origin rpy="0 0 0" xyz="0.2 0 0"/>
    <parent link="chassis"/>
    <child link="camera_link"/>
  </joint>
  <link name="hokuyo_link">
    <inertial>
      <origin rpy="0 0 0" xyz="0 0 0"/>
      <!--<mass value="${min_mass}"/>-->
      <mass value="0.1"/>
      <inertia ixx="0.1" ixy="0" ixz="0" iyy="0.1" iyz="0" izz="0.1"/>
    </inertial>
    <collision>
      <origin rpy="0 0 0" xyz="0 0 0"/>
      <!--UNITS IN METERS-->
      <!--<cylinder radius="" length=""/>-->
      <!--<box x="" y="" z="" />-->
      <!--<sphere radius=""/> -->
      <geometry>
        <box size="0.1 0.1 0.1"/>
      </geometry>
    </collision>
    <visual>
      <origin rpy="0 0 0" xyz="0 0 0"/>
      <!--<xacro:generate_geometry shape="box" x="0.05" y="0.05" z="0.05"/>-->
      <geometry>
        <mesh filename="package://udacity_bot/models/meshes/hokuyo.dae"/>
      </geometry>
    </visual>
  </link>
  <joint name="hokuyo_joint" type="fixed">
    <origin rpy="0 0 0" xyz="0.15 0 0.1"/>
    <parent link="chassis"/>
    <child link="hokuyo_link"/>
  </joint>
</robot>

